<sdf version="1.6">
  <world name="factory_open">
    <physics name="1ms" type="ode">
      <max_step_size>0.001</max_step_size>
      <real_time_factor>1.0</real_time_factor>
      <real_time_update_rate>1000</real_time_update_rate>
    </physics>
    <plugin filename="gz-sim-physics-system" name="gz::sim::systems::Physics"/>
    <plugin filename="gz-sim-sensors-system" name="gz::sim::systems::Sensors">
      <render_engine>ogre2</render_engine>
    </plugin>
    <plugin filename="gz-sim-scene-broadcaster-system" name="gz::sim::systems::SceneBroadcaster"/>
    <plugin filename="gz-sim-user-commands-system" name="gz::sim::systems::UserCommands"/>
    <plugin filename="gz-sim-imu-system" name="gz::sim::systems::Imu"/>
    <gravity>0 0 -9.81</gravity>
    <light type="directional" name="sun">
      <cast_shadows>true</cast_shadows><pose>0 0 15 0 0 0</pose>
      <diffuse>0.9 0.9 0.9</diffuse><direction>-0.4 0.2 -0.9</direction>
    </light>
    <model name="ground"><static>true</static>
      <link name="l"><collision name="c"><geometry><box><size>60 60 0.1</size></box></geometry></collision>
        <visual name="v"><geometry><box><size>60 60 0.1</size></box></geometry>
          <material><ambient>0.5 0.5 0.5</ambient><diffuse>0.65 0.65 0.65</diffuse></material></visual></link></model>

<!-- ================================================================
     布局: 30×30 围墙封闭 | 十字主走廊 | 四个开放房间区
================================================================ -->

<!-- ====== 外围围墙 ====== -->
<model name="wall_n"><static>true</static><pose>0 15 2.5 0 0 0</pose>
  <link name="l"><collision name="c"><geometry><box><size>30 0.4 5</size></box></geometry></collision>
    <visual name="v"><geometry><box><size>30 0.4 5</size></box></geometry>
      <material><ambient>0.7 0.35 0.25</ambient><diffuse>0.75 0.4 0.3</diffuse></material></visual></link></model>
<model name="wall_s"><static>true</static><pose>0 -15 2.5 0 0 0</pose>
  <link name="l"><collision name="c"><geometry><box><size>30 0.4 5</size></box></geometry></collision>
    <visual name="v"><geometry><box><size>30 0.4 5</size></box></geometry>
      <material><ambient>0.3 0.4 0.7</ambient><diffuse>0.35 0.45 0.75</diffuse></material></visual></link></model>
<model name="wall_e"><static>true</static><pose>15 0 2.5 0 0 1.57</pose>
  <link name="l"><collision name="c"><geometry><box><size>30 0.4 5</size></box></geometry></collision>
    <visual name="v"><geometry><box><size>30 0.4 5</size></box></geometry>
      <material><ambient>0.35 0.7 0.35</ambient><diffuse>0.4 0.75 0.4</diffuse></material></visual></link></model>
<model name="wall_w"><static>true</static><pose>-15 0 2.5 0 0 1.57</pose>
  <link name="l"><collision name="c"><geometry><box><size>30 0.4 5</size></box></geometry></collision>
    <visual name="v"><geometry><box><size>30 0.4 5</size></box></geometry>
      <material><ambient>0.75 0.65 0.2</ambient><diffuse>0.8 0.7 0.25</diffuse></material></visual></link></model>

<!-- ====== 内部障碍物 ====== -->
<!-- NE 区 -->
<model name="ne_w1"><static>true</static><pose>10 8 2 0 0 0</pose>
  <link name="l"><collision name="c"><geometry><box><size>4 0.25 4</size></box></geometry></collision>
    <visual name="v"><geometry><box><size>4 0.25 4</size></box></geometry>
      <material><ambient>0.6 0.55 0.55</ambient><diffuse>0.7 0.65 0.65</diffuse></material></visual></link></model>
<model name="ne_w2"><static>true</static><pose>8 10 2 0 0 1.57</pose>
  <link name="l"><collision name="c"><geometry><box><size>3 0.25 4</size></box></geometry></collision>
    <visual name="v"><geometry><box><size>3 0.25 4</size></box></geometry>
      <material><ambient>0.55 0.6 0.55</ambient><diffuse>0.65 0.7 0.65</diffuse></material></visual></link></model>
<model name="ne_p1"><static>true</static><pose>12 10 2.5 0 0 0</pose>
  <link name="l"><collision name="c"><geometry><cylinder><radius>0.4</radius><length>5</length></cylinder></geometry></collision>
    <visual name="v"><geometry><cylinder><radius>0.4</radius><length>5</length></cylinder></geometry>
      <material><ambient>0.5 0.5 0.5</ambient><diffuse>0.6 0.6 0.6</diffuse></material></visual></link></model>
<model name="ne_shelf"><static>true</static><pose>10 6 1.2 0 0 0.1</pose>
  <link name="l"><collision name="c"><geometry><box><size>2 1 2.4</size></box></geometry></collision>
    <visual name="v"><geometry><box><size>2 1 2.4</size></box></geometry>
      <material><ambient>0.7 0.45 0.2</ambient><diffuse>0.75 0.5 0.25</diffuse></material></visual></link></model>

<!-- NW 区 -->
<model name="nw_w1"><static>true</static><pose>-10 8 2 0 0 0</pose>
  <link name="l"><collision name="c"><geometry><box><size>5 0.25 4</size></box></geometry></collision>
    <visual name="v"><geometry><box><size>5 0.25 4</size></box></geometry>
      <material><ambient>0.55 0.55 0.6</ambient><diffuse>0.65 0.65 0.7</diffuse></material></visual></link></model>
<model name="nw_w2"><static>true</static><pose>-8 10 2 0 0 1.57</pose>
  <link name="l"><collision name="c"><geometry><box><size>4 0.25 4</size></box></geometry></collision>
    <visual name="v"><geometry><box><size>4 0.25 4</size></box></geometry>
      <material><ambient>0.55 0.6 0.6</ambient><diffuse>0.65 0.7 0.7</diffuse></material></visual></link></model>
<model name="nw_p1"><static>true</static><pose>-12 10 2.5 0 0 0</pose>
  <link name="l"><collision name="c"><geometry><cylinder><radius>0.45</radius><length>5</length></cylinder></geometry></collision>
    <visual name="v"><geometry><cylinder><radius>0.45</radius><length>5</length></cylinder></geometry>
      <material><ambient>0.5 0.5 0.5</ambient><diffuse>0.6 0.6 0.6</diffuse></material></visual></link></model>
<model name="nw_cr1"><static>true</static><pose>-10 6 0.6 0 0 0</pose>
  <link name="l"><collision name="c"><geometry><box><size>1.5 1.5 1.2</size></box></geometry></collision>
    <visual name="v"><geometry><box><size>1.5 1.5 1.2</size></box></geometry>
      <material><ambient>0.35 0.55 0.7</ambient><diffuse>0.4 0.6 0.75</diffuse></material></visual></link></model>

<!-- SW 区 -->
<model name="sw_w1"><static>true</static><pose>-10 -8 2 0 0 0</pose>
  <link name="l"><collision name="c"><geometry><box><size>4 0.25 4</size></box></geometry></collision>
    <visual name="v"><geometry><box><size>4 0.25 4</size></box></geometry>
      <material><ambient>0.55 0.55 0.55</ambient><diffuse>0.65 0.65 0.65</diffuse></material></visual></link></model>
<model name="sw_p1"><static>true</static><pose>-12 -9 2.5 0 0 0</pose>
  <link name="l"><collision name="c"><geometry><cylinder><radius>0.4</radius><length>5</length></cylinder></geometry></collision>
    <visual name="v"><geometry><cylinder><radius>0.4</radius><length>5</length></cylinder></geometry>
      <material><ambient>0.5 0.5 0.5</ambient><diffuse>0.6 0.6 0.6</diffuse></material></visual></link></model>
<model name="sw_p2"><static>true</static><pose>-8 -11 2 0 0 0</pose>
  <link name="l"><collision name="c"><geometry><cylinder><radius>0.35</radius><length>4</length></cylinder></geometry></collision>
    <visual name="v"><geometry><cylinder><radius>0.35</radius><length>4</length></cylinder></geometry>
      <material><ambient>0.5 0.5 0.5</ambient><diffuse>0.6 0.6 0.6</diffuse></material></visual></link></model>

<!-- SE 区 -->
<model name="se_w1"><static>true</static><pose>10 -8 2 0 0 0</pose>
  <link name="l"><collision name="c"><geometry><box><size>5 0.25 4</size></box></geometry></collision>
    <visual name="v"><geometry><box><size>5 0.25 4</size></box></geometry>
      <material><ambient>0.6 0.55 0.5</ambient><diffuse>0.7 0.65 0.6</diffuse></material></visual></link></model>
<model name="se_p1"><static>true</static><pose>10 -11 2.5 0 0 0</pose>
  <link name="l"><collision name="c"><geometry><cylinder><radius>0.45</radius><length>5</length></cylinder></geometry></collision>
    <visual name="v"><geometry><cylinder><radius>0.45</radius><length>5</length></cylinder></geometry>
      <material><ambient>0.5 0.5 0.5</ambient><diffuse>0.6 0.6 0.6</diffuse></material></visual></link></model>
<model name="se_cr1"><static>true</static><pose>8 -11 0.7 0 0 0.2</pose>
  <link name="l"><collision name="c"><geometry><box><size>1.5 1 1.4</size></box></geometry></collision>
    <visual name="v"><geometry><box><size>1.5 1 1.4</size></box></geometry>
      <material><ambient>0.6 0.4 0.35</ambient><diffuse>0.65 0.45 0.4</diffuse></material></visual></link></model>

<!-- 中央十字通道 -->
<model name="cc_nw"><static>true</static><pose>-3 3 2 0 0 0</pose>
  <link name="l"><collision name="c"><geometry><cylinder><radius>0.3</radius><length>4</length></cylinder></geometry></collision>
    <visual name="v"><geometry><cylinder><radius>0.3</radius><length>4</length></cylinder></geometry>
      <material><ambient>0.5 0.45 0.5</ambient><diffuse>0.6 0.55 0.6</diffuse></material></visual></link></model>
<model name="cc_ne"><static>true</static><pose>3 3 2 0 0 0</pose>
  <link name="l"><collision name="c"><geometry><cylinder><radius>0.3</radius><length>4</length></cylinder></geometry></collision>
    <visual name="v"><geometry><cylinder><radius>0.3</radius><length>4</length></cylinder></geometry>
      <material><ambient>0.5 0.5 0.45</ambient><diffuse>0.6 0.6 0.55</diffuse></material></visual></link></model>
<model name="cc_sw"><static>true</static><pose>-3 -3 2 0 0 0</pose>
  <link name="l"><collision name="c"><geometry><cylinder><radius>0.3</radius><length>4</length></cylinder></geometry></collision>
    <visual name="v"><geometry><cylinder><radius>0.3</radius><length>4</length></cylinder></geometry>
      <material><ambient>0.5 0.5 0.45</ambient><diffuse>0.6 0.6 0.55</diffuse></material></visual></link></model>
<model name="cc_se"><static>true</static><pose>3 -3 2 0 0 0</pose>
  <link name="l"><collision name="c"><geometry><cylinder><radius>0.3</radius><length>4</length></cylinder></geometry></collision>
    <visual name="v"><geometry><cylinder><radius>0.3</radius><length>4</length></cylinder></geometry>
      <material><ambient>0.45 0.5 0.5</ambient><diffuse>0.55 0.6 0.6</diffuse></material></visual></link></model>

<!-- 散布柱子 -->
<model name="p_a"><static>true</static><pose>5 7 2 0 0 0</pose>
  <link name="l"><collision name="c"><geometry><cylinder><radius>0.25</radius><length>4</length></cylinder></geometry></collision>
    <visual name="v"><geometry><cylinder><radius>0.25</radius><length>4</length></cylinder></geometry>
      <material><ambient>0.5 0.5 0.5</ambient><diffuse>0.6 0.6 0.6</diffuse></material></visual></link></model>
<model name="p_b"><static>true</static><pose>-5 7 2 0 0 0</pose>
  <link name="l"><collision name="c"><geometry><cylinder><radius>0.35</radius><length>4</length></cylinder></geometry></collision>
    <visual name="v"><geometry><cylinder><radius>0.35</radius><length>4</length></cylinder></geometry>
      <material><ambient>0.5 0.5 0.5</ambient><diffuse>0.6 0.6 0.6</diffuse></material></visual></link></model>
<model name="p_c"><static>true</static><pose>7 -5 2 0 0 0</pose>
  <link name="l"><collision name="c"><geometry><cylinder><radius>0.3</radius><length>4</length></cylinder></geometry></collision>
    <visual name="v"><geometry><cylinder><radius>0.3</radius><length>4</length></cylinder></geometry>
      <material><ambient>0.5 0.5 0.5</ambient><diffuse>0.6 0.6 0.6</diffuse></material></visual></link></model>
<model name="p_d"><static>true</static><pose>-7 -5 2 0 0 0</pose>
  <link name="l"><collision name="c"><geometry><cylinder><radius>0.3</radius><length>4</length></cylinder></geometry></collision>
    <visual name="v"><geometry><cylinder><radius>0.3</radius><length>4</length></cylinder></geometry>
      <material><ambient>0.5 0.5 0.5</ambient><diffuse>0.6 0.6 0.6</diffuse></material></visual></link></model>
<model name="p_e"><static>true</static><pose>0 7 2 0 0 0</pose>
  <link name="l"><collision name="c"><geometry><cylinder><radius>0.2</radius><length>4</length></cylinder></geometry></collision>
    <visual name="v"><geometry><cylinder><radius>0.2</radius><length>4</length></cylinder></geometry>
      <material><ambient>0.5 0.5 0.5</ambient><diffuse>0.6 0.6 0.6</diffuse></material></visual></link></model>
<model name="p_f"><static>true</static><pose>0 -7 2 0 0 0</pose>
  <link name="l"><collision name="c"><geometry><cylinder><radius>0.2</radius><length>4</length></cylinder></geometry></collision>
    <visual name="v"><geometry><cylinder><radius>0.2</radius><length>4</length></cylinder></geometry>
      <material><ambient>0.5 0.5 0.5</ambient><diffuse>0.6 0.6 0.6</diffuse></material></visual></link></model>

<!-- 箱子 -->
<model name="cr_a"><static>true</static><pose>4 -8 0.6 0 0 0.3</pose>
  <link name="l"><collision name="c"><geometry><box><size>1.2 1.2 1.2</size></box></geometry></collision>
    <visual name="v"><geometry><box><size>1.2 1.2 1.2</size></box></geometry>
      <material><ambient>0.3 0.65 0.35</ambient><diffuse>0.35 0.7 0.4</diffuse></material></visual></link></model>
<model name="cr_b"><static>true</static><pose>-4 8 0.6 0 0 0</pose>
  <link name="l"><collision name="c"><geometry><box><size>1 1.4 1.2</size></box></geometry></collision>
    <visual name="v"><geometry><box><size>1 1.4 1.2</size></box></geometry>
      <material><ambient>0.7 0.25 0.5</ambient><diffuse>0.75 0.3 0.55</diffuse></material></visual></link></model>
<model name="cr_c"><static>true</static><pose>7 4 0.55 0 0 0.15</pose>
  <link name="l"><collision name="c"><geometry><box><size>0.8 1.6 1.1</size></box></geometry></collision>
    <visual name="v"><geometry><box><size>0.8 1.6 1.1</size></box></geometry>
      <material><ambient>0.75 0.6 0.2</ambient><diffuse>0.8 0.65 0.25</diffuse></material></visual></link></model>
<model name="cr_d"><static>true</static><pose>-7 -4 0.55 0 0 0</pose>
  <link name="l"><collision name="c"><geometry><box><size>1.5 0.9 1.1</size></box></geometry></collision>
    <visual name="v"><geometry><box><size>1.5 0.9 1.1</size></box></geometry>
      <material><ambient>0.4 0.35 0.7</ambient><diffuse>0.45 0.4 0.75</diffuse></material></visual></link></model>

<!-- 货架 -->
<model name="sh_A"><static>true</static><pose>6 2 1.4 0 0 0</pose>
  <link name="l"><collision name="c"><geometry><box><size>2.5 0.8 2.8</size></box></geometry></collision>
    <visual name="v"><geometry><box><size>2.5 0.8 2.8</size></box></geometry>
      <material><ambient>0.6 0.45 0.3</ambient><diffuse>0.65 0.5 0.35</diffuse></material></visual></link></model>
<model name="sh_B"><static>true</static><pose>-6 -2 1.3 0 0 0.2</pose>
  <link name="l"><collision name="c"><geometry><box><size>2 0.9 2.6</size></box></geometry></collision>
    <visual name="v"><geometry><box><size>2 0.9 2.6</size></box></geometry>
      <material><ambient>0.35 0.5 0.65</ambient><diffuse>0.4 0.55 0.7</diffuse></material></visual></link></model>
<model name="sh_C"><static>true</static><pose>2 6 1.1 0 0 0.1</pose>
  <link name="l"><collision name="c"><geometry><box><size>1.8 1.2 2.2</size></box></geometry></collision>
    <visual name="v"><geometry><box><size>1.8 1.2 2.2</size></box></geometry>
      <material><ambient>0.55 0.35 0.55</ambient><diffuse>0.6 0.4 0.6</diffuse></material></visual></link></model>
<model name="sh_D"><static>true</static><pose>-2 -6 1.0 0 0 0.3</pose>
  <link name="l"><collision name="c"><geometry><box><size>1.6 1.1 2</size></box></geometry></collision>
    <visual name="v"><geometry><box><size>1.6 1.1 2</size></box></geometry>
      <material><ambient>0.6 0.55 0.25</ambient><diffuse>0.65 0.6 0.3</diffuse></material></visual></link></model>

<!-- 油桶 -->
<model name="brl_1"><static>true</static><pose>-8 0 0.8 0 0 0</pose>
  <link name="l"><collision name="c"><geometry><cylinder><radius>0.4</radius><length>1.6</length></cylinder></geometry></collision>
    <visual name="v"><geometry><cylinder><radius>0.4</radius><length>1.6</length></cylinder></geometry>
      <material><ambient>0.7 0.5 0.2</ambient><diffuse>0.75 0.55 0.25</diffuse></material></visual></link></model>
<model name="brl_2"><static>true</static><pose>8 0 0.8 0 0 0</pose>
  <link name="l"><collision name="c"><geometry><cylinder><radius>0.35</radius><length>1.6</length></cylinder></geometry></collision>
    <visual name="v"><geometry><cylinder><radius>0.35</radius><length>1.6</length></cylinder></geometry>
      <material><ambient>0.65 0.4 0.25</ambient><diffuse>0.7 0.45 0.3</diffuse></material></visual></link></model>
<model name="brl_3"><static>true</static><pose>0 -8 0.8 0 0 0</pose>
  <link name="l"><collision name="c"><geometry><cylinder><radius>0.3</radius><length>1.6</length></cylinder></geometry></collision>
    <visual name="v"><geometry><cylinder><radius>0.3</radius><length>1.6</length></cylinder></geometry>
      <material><ambient>0.7 0.45 0.3</ambient><diffuse>0.75 0.5 0.35</diffuse></material></visual></link></model>

<!-- 斜坡 -->
<model name="ramp_1"><static>true</static><pose>4 4 0.3 0 0.35 0</pose>
  <link name="l"><collision name="c"><geometry><box><size>5 2 0.3</size></box></geometry></collision>
    <visual name="v"><geometry><box><size>5 2 0.3</size></box></geometry>
      <material><ambient>0.45 0.45 0.45</ambient><diffuse>0.55 0.55 0.55</diffuse></material></visual></link></model>
<model name="ramp_2"><static>true</static><pose>-4 -4 0.3 0 -0.35 0</pose>
  <link name="l"><collision name="c"><geometry><box><size>5 2 0.3</size></box></geometry></collision>
    <visual name="v"><geometry><box><size>5 2 0.3</size></box></geometry>
      <material><ambient>0.45 0.45 0.45</ambient><diffuse>0.55 0.55 0.55</diffuse></material></visual></link></model>
<model name="ramp_3"><static>true</static><pose>8 -6 0.3 0 0.35 1.57</pose>
  <link name="l"><collision name="c"><geometry><box><size>5 2 0.3</size></box></geometry></collision>
    <visual name="v"><geometry><box><size>5 2 0.3</size></box></geometry>
      <material><ambient>0.45 0.45 0.45</ambient><diffuse>0.55 0.55 0.55</diffuse></material></visual></link></model>

<!-- ====== 检测目标: 红色球体 (椅子不可见面, 球在 NE区货架旁) ====== -->
<model name="target_ball"><static>true</static>
  <pose>12 5 0.5 0 0 0</pose>
  <link name="ball">
    <visual name="v">
      <geometry><sphere><radius>0.35</radius></sphere></geometry>
      <material><ambient>0.9 0.1 0.1</ambient><diffuse>0.9 0.1 0.1</diffuse></material>
    </visual>
  </link>
</model>
<model name="target_chair"><static>true</static>
  <pose>10 10 0.5 0 0 0</pose>
  <link name="chair">
    <visual name="v">
      <geometry><box><size>0.5 0.5 0.8</size></box></geometry>
      <material><ambient>0.1 0.1 0.1</ambient><diffuse>0.15 0.15 0.15</diffuse></material>
    </visual>
  </link>
</model>

<!-- ====== 差速轮式机器人 ====== -->
<model name="robot">
  <pose>0 0 0.20 0 0 0</pose>

  <!-- ============================================================
       base_link: 轮轴中心点 (Z=0.20 in world, r=0.2 wheel touches ground)
       车身尺寸: 0.9m(长) x 0.6m(宽) x 0.3m(高)
       轮距: 0.60m (Y=±0.30)
       wheel_radius: 0.20m
  ============================================================ -->

  <link name="base_link">
    <inertial>
      <mass>8.0</mass>
      <inertia><ixx>1.5</ixx><iyy>1.5</iyy><izz>2.0</izz></inertia>
    </inertial>
    <!-- 车身 (轮轴上方) -->
    <collision name="body_collision">
      <pose>0 0 0.22 0 0 0</pose>
      <geometry><box><size>0.9 0.6 0.3</size></box></geometry>
      <surface><friction><ode><mu>1.0</mu><mu2>1.0</mu2></ode></friction></surface>
    </collision>
    <visual name="body_visual">
      <pose>0 0 0.22 0 0 0</pose>
      <geometry><box><size>0.9 0.6 0.3</size></box></geometry>
      <material><ambient>0.2 0.25 0.45</ambient><diffuse>0.3 0.35 0.6</diffuse></material>
    </visual>
    <!-- IMU -->
    <sensor name="imu_sensor" type="imu">
      <topic>/robot/imu</topic>
      <always_on>1</always_on>
      <update_rate>400</update_rate>
    </sensor>
  </link>

  <!-- ====== LiDAR: 车顶中央 ====== -->
  <link name="lidar_link">
    <pose>0 0 0.40 0 0 0</pose>
    <inertial><mass>0.3</mass><inertia><ixx>0.01</ixx><iyy>0.01</iyy><izz>0.01</izz></inertia></inertial>
    <visual name="lidar_visual">
      <geometry><cylinder><radius>0.08</radius><length>0.08</length></cylinder></geometry>
      <material><ambient>0.1 0.1 0.1</ambient><diffuse>0.2 0.2 0.2</diffuse></material>
    </visual>
    <sensor name="lidar_sensor" type="gpu_lidar">
      <topic>/robot/lidar</topic>
      <update_rate>10</update_rate>
      <lidar>
        <scan>
          <horizontal><samples>900</samples><resolution>1</resolution>
            <min_angle>-3.14159</min_angle><max_angle>3.14159</max_angle></horizontal>
          <vertical><samples>16</samples><resolution>1</resolution>
            <min_angle>-0.261799</min_angle><max_angle>0.261799</max_angle></vertical>
        </scan>
        <range><min>0.3</min><max>50.0</max><resolution>0.02</resolution></range>
        <noise><type>gaussian</type><mean>0</mean><stddev>0.03</stddev></noise>
      </lidar>
      <always_on>1</always_on>
      <visualize>true</visualize>
    </sensor>
  </link>
  <joint name="lidar_joint" type="fixed">
    <parent>base_link</parent>
    <child>lidar_link</child>
  </joint>

  <!-- ====== Camera: 车身前方 ====== -->
  <link name="camera_link">
    <pose>0.42 0 0.30 0 0 0</pose>
    <inertial><mass>0.05</mass>
      <inertia><ixx>0.0001</ixx><iyy>0.0001</iyy><izz>0.0001</izz></inertia></inertial>
    <visual name="camera_visual">
      <geometry><box><size>0.06 0.04 0.03</size></box></geometry>
      <material><ambient>0.1 0.1 0.1</ambient><diffuse>0.2 0.2 0.2</diffuse></material>
    </visual>
    <sensor name="camera_sensor" type="camera">
      <topic>/robot/camera</topic>
      <camera>
        <horizontal_fov>1.047</horizontal_fov>
        <image><width>640</width><height>480</height><format>R8G8B8</format></image>
        <clip><near>0.1</near><far>100</far></clip>
      </camera>
      <always_on>1</always_on>
      <update_rate>30</update_rate>
      <visualize>true</visualize>
    </sensor>
  </link>
  <joint name="camera_joint" type="fixed">
    <parent>base_link</parent>
    <child>camera_link</child>
  </joint>

  <!-- ====== DiffDrive 插件 ====== -->
  <plugin filename="gz-sim-diff-drive-system" name="gz::sim::systems::DiffDrive">
    <left_joint>rear_left_joint</left_joint>
    <right_joint>rear_right_joint</right_joint>
    <wheel_separation>0.60</wheel_separation>
    <wheel_radius>0.20</wheel_radius>
    <max_linear_acceleration>0.8</max_linear_acceleration>
    <max_angular_acceleration>1.5</max_angular_acceleration>
    <odom_publish_frequency>30</odom_publish_frequency>
  </plugin>

  <!-- ====== 后左驱动轮 ====== -->
  <link name="rear_left_wheel">
    <pose>-0.25 -0.30 0.00 0 0 0</pose>
    <inertial><mass>0.8</mass>
      <inertia><ixx>0.008</ixx><iyy>0.008</iyy><izz>0.016</izz></inertia></inertial>
    <collision name="c">
      <pose>0 0 0 -1.5707 0 0</pose>
      <geometry><cylinder><radius>0.20</radius><length>0.06</length></cylinder></geometry>
      <surface><friction><ode><mu>1.0</mu><mu2>1.0</mu2></ode></friction></surface>
    </collision>
    <visual name="v">
      <pose>0 0 0 -1.5707 0 0</pose>
      <geometry><cylinder><radius>0.20</radius><length>0.06</length></cylinder></geometry>
      <material><ambient>0.15 0.15 0.15</ambient><diffuse>0.25 0.25 0.25</diffuse></material>
    </visual>
  </link>
  <joint name="rear_left_joint" type="revolute">
    <parent>base_link</parent>
    <child>rear_left_wheel</child>
    <axis><xyz>0 1 0</xyz></axis>
    <dynamics><damping>3.0</damping><friction>2.0</friction></dynamics>
  </joint>

  <!-- ====== 后右驱动轮 ====== -->
  <link name="rear_right_wheel">
    <pose>-0.25 0.30 0.00 0 0 0</pose>
    <inertial><mass>0.8</mass>
      <inertia><ixx>0.008</ixx><iyy>0.008</iyy><izz>0.016</izz></inertia></inertial>
    <collision name="c">
      <pose>0 0 0 -1.5707 0 0</pose>
      <geometry><cylinder><radius>0.20</radius><length>0.06</length></cylinder></geometry>
      <surface><friction><ode><mu>1.0</mu><mu2>1.0</mu2></ode></friction></surface>
    </collision>
    <visual name="v">
      <pose>0 0 0 -1.5707 0 0</pose>
      <geometry><cylinder><radius>0.20</radius><length>0.06</length></cylinder></geometry>
      <material><ambient>0.15 0.15 0.15</ambient><diffuse>0.25 0.25 0.25</diffuse></material>
    </visual>
  </link>
  <joint name="rear_right_joint" type="revolute">
    <parent>base_link</parent>
    <child>rear_right_wheel</child>
    <axis><xyz>0 1 0</xyz></axis>
    <dynamics><damping>3.0</damping><friction>2.0</friction></dynamics>
  </joint>

  <!-- ====== 前左从动轮 ====== -->
  <link name="front_left_wheel">
    <pose>0.32 -0.30 0.00 0 0 0</pose>
    <inertial><mass>0.5</mass>
      <inertia><ixx>0.005</ixx><iyy>0.005</iyy><izz>0.010</izz></inertia></inertial>
    <collision name="c">
      <pose>0 0 0 -1.5707 0 0</pose>
      <geometry><cylinder><radius>0.20</radius><length>0.06</length></cylinder></geometry>
      <surface><friction><ode><mu>0.1</mu><mu2>0.1</mu2></ode></friction></surface>
    </collision>
    <visual name="v">
      <pose>0 0 0 -1.5707 0 0</pose>
      <geometry><cylinder><radius>0.20</radius><length>0.06</length></cylinder></geometry>
      <material><ambient>0.12 0.12 0.12</ambient><diffuse>0.20 0.20 0.20</diffuse></material>
    </visual>
  </link>
  <joint name="front_left_joint" type="revolute">
    <parent>base_link</parent>
    <child>front_left_wheel</child>
    <axis><xyz>0 1 0</xyz></axis>
    <dynamics><damping>2.0</damping><friction>1.0</friction></dynamics>
  </joint>

  <!-- ====== 前右从动轮 ====== -->
  <link name="front_right_wheel">
    <pose>0.32 0.30 0.00 0 0 0</pose>
    <inertial><mass>0.5</mass>
      <inertia><ixx>0.005</ixx><iyy>0.005</iyy><izz>0.010</izz></inertia></inertial>
    <collision name="c">
      <pose>0 0 0 -1.5707 0 0</pose>
      <geometry><cylinder><radius>0.20</radius><length>0.06</length></cylinder></geometry>
      <surface><friction><ode><mu>0.1</mu><mu2>0.1</mu2></ode></friction></surface>
    </collision>
    <visual name="v">
      <pose>0 0 0 -1.5707 0 0</pose>
      <geometry><cylinder><radius>0.20</radius><length>0.06</length></cylinder></geometry>
      <material><ambient>0.12 0.12 0.12</ambient><diffuse>0.20 0.20 0.20</diffuse></material>
    </visual>
  </link>
  <joint name="front_right_joint" type="revolute">
    <parent>base_link</parent>
    <child>front_right_wheel</child>
    <axis><xyz>0 1 0</xyz></axis>
    <dynamics><damping>2.0</damping><friction>1.0</friction></dynamics>
  </joint>
</model>


  </world>
</sdf>
